Workbook

Sheet Analytics
B2: Capital One Card Report
B4: Generated: | C4: 46210.65
B5: Date range (Transaction): | C5: 5/16/2026 – 6/16/2026
B6: Card number(s): | C6: 3390, 4419, 5527, 7761, 8102
B8: OVERVIEW
B9: Total transactions: | C9: 92
B10: Grand Total (Debit): | C10: ='Capital One Card'!C133
B11: Grand Total (Credit): | C11: ='Capital One Card'!D133
B13: BY CATEGORY
B14: Category | C14: Transactions | D14: Debit | E14: Credit
B15: Dining | C15: 8 | D15: ='Capital One Card'!C11 | E15: ='Capital One Card'!D11
B16: Entertainment | C16: 9 | D16: ='Capital One Card'!C23 | E16: ='Capital One Card'!D23
B17: Gas/Automotive | C17: 10 | D17: ='Capital One Card'!C36 | E17: ='Capital One Card'!D36
B18: Health Care | C18: 4 | D18: ='Capital One Card'!C43 | E18: ='Capital One Card'!D43
B19: Insurance | C19: 1 | D19: ='Capital One Card'!C47 | E19: ='Capital One Card'!D47
B20: Internet | C20: 6 | D20: ='Capital One Card'!C56 | E20: ='Capital One Card'!D56
B21: Lodging | C21: 3 | D21: ='Capital One Card'!C62 | E21: ='Capital One Card'!D62
B22: Merchandise | C22: 25 | D22: ='Capital One Card'!C90 | E22: ='Capital One Card'!D90
B23: Other | C23: 3 | D23: ='Capital One Card'!C96 | E23: ='Capital One Card'!D96
B24: Other Services | C24: 12 | D24: ='Capital One Card'!C111 | E24: ='Capital One Card'!D111
B25: Other Travel | C25: 6 | D25: ='Capital One Card'!C120 | E25: ='Capital One Card'!D120
B26: Payment/Credit | C26: 3 | D26: ='Capital One Card'!C126 | E26: ='Capital One Card'!D126
B27: Professional Services | C27: 2 | D27: ='Capital One Card'!C131 | E27: ='Capital One Card'!D131

Sheet Capital One Card
A1: Transaction Date | B1: Description | C1: Debit | D1: Credit
A2: Dining
A3: 46187 | B3: CHIPOTLE 1885 | C3: 24.65
A4: 46181 | B4: DOORDASH*RUBIOS COASTAL | C4: 99.06
A5: 46180 | B5: HEIRLOOM A MODERN FARM | C5: 196.97
A6: 46165 | B6: IN-N-OUT BURGER #112 | C6: 18.34
A7: 46183 | B7: SQ *MAJESTIC INDUSTRY | C7: 39.51
A8: 46161 | B8: SQ *MAJESTIC REFUND | D8: 39.51
A9: 46186 | B9: STARBUCKS #08812 | C9: 6.75
A10: 46175 | B10: TST*MARIO'S BUTCHERY & | C10: 130.84
A11: Dining Total | C11: =SUM(C3:C10) | D11: =SUM(D3:D10)
A13: Entertainment
A14: 46173 | B14: AUDIBLE*BW2QY7 | C14: 14.95
A15: 46160 | B15: BVE*BeenVerified.com | C15: 32.89
A16: 46168 | B16: CEP*THE HUNTINGTON CL | C16: 1981.27
A17: 46179 | B17: CROSSFIT SURF CITY | C17: 370
A18: 46166 | B18: FSP*T & A JUMPERS AND | C18: 579.65
A19: 46176 | B19: HULU 877-8244858 | C19: 17.99
A20: 46183 | B20: LA FITNESS 000000 | C20: 34.99
A21: 46168 | B21: SIRIUSXM.COM/ACCT | C21: 21.99
A22: 46187 | B22: SPOTIFY USA | C22: 11.99
A23: Entertainment Total | C23: =SUM(C14:C22) | D23: =SUM(D14:D22)
A25: Gas/Automotive
A26: 46173 | B26: 76 - APRO LLC 2708886 | C26: 100.14
A27: 46172 | B27: ACE PARKING 2604 | C27: 3
A28: 46181 | B28: ARCO 915737 | C28: 107.94
A29: 46185 | B29: CHEVRON 0356005 | C29: 114.94
A30: 46183 | B30: EXXON HB FUELS INC | C30: 70.24
A31: 46174 | B31: FROGS EXPRESS WASH | C31: 11.4
A32: 46168 | B32: SHELL OIL 12651332004 | C32: 1.08
A33: 46188 | B33: SHELL OIL 57444291 | C33: 52.18
A34: 46163 | B34: THE DEPOT 3 | C34: 10.25
A35: 46175 | B35: THE TOLL ROADS OF OC | C35: 55
A36: Gas/Automotive Total | C36: =SUM(C26:C35) | D36: =SUM(D26:D35)
A38: Health Care
A39: 46173 | B39: BLVD *HYDRATION ROOM | C39: 149
A40: 46161 | B40: CVS/PHARMACY #09823 | C40: 42.68
A41: 46174 | B41: FUNCTION HEALTH | C41: 948
A42: 46185 | B42: IN *IOSM DBA ON-SITE H | C42: 615
A43: Health Care Total | C43: =SUM(C39:C42) | D43: =SUM(D39:D42)
...
